<mujoco model="factorymind_cell">
  <compiler angle="radian" meshdir="menagerie/assets/"/>

  <size nkey="2"/>

  <visual>
    <global offwidth="1280" offheight="720"/>
    <headlight ambient="0.42 0.42 0.44" diffuse="0.55 0.55 0.58" specular="0.12 0.12 0.12"/>
  </visual>

  <default>
    <default class="arm0_main">
      <default class="arm0_panda">
        <material shininess="0.25"/>
        <joint range="-2.8973 2.8973" armature="0.1" damping="1"/>
        <general ctrlrange="-2.8973 2.8973" forcerange="-87 87" biastype="affine"/>
        <default class="arm0_finger">
          <joint type="slide" range="0 0.04"/>
        </default>
        <default class="arm0_visual">
          <geom type="mesh" contype="0" conaffinity="0" group="2"/>
        </default>
        <default class="arm0_collision">
          <geom type="mesh" group="3"/>
          <default class="arm0_fingertip_pad_collision_1">
            <geom size="0.0085 0.004 0.0085" type="box"/>
          </default>
          <default class="arm0_fingertip_pad_collision_2">
            <geom size="0.003 0.002 0.003" type="box"/>
          </default>
          <default class="arm0_fingertip_pad_collision_3">
            <geom size="0.003 0.002 0.003" type="box"/>
          </default>
          <default class="arm0_fingertip_pad_collision_4">
            <geom size="0.003 0.002 0.0035" type="box"/>
          </default>
          <default class="arm0_fingertip_pad_collision_5">
            <geom size="0.003 0.002 0.0035" type="box"/>
          </default>
        </default>
      </default>
    </default>
    <default class="arm1_main">
      <default class="arm1_panda">
        <material shininess="0.25"/>
        <joint range="-2.8973 2.8973" armature="0.1" damping="1"/>
        <general ctrlrange="-2.8973 2.8973" forcerange="-87 87" biastype="affine"/>
        <default class="arm1_finger">
          <joint type="slide" range="0 0.04"/>
        </default>
        <default class="arm1_visual">
          <geom type="mesh" contype="0" conaffinity="0" group="2"/>
        </default>
        <default class="arm1_collision">
          <geom type="mesh" group="3"/>
          <default class="arm1_fingertip_pad_collision_1">
            <geom size="0.0085 0.004 0.0085" type="box"/>
          </default>
          <default class="arm1_fingertip_pad_collision_2">
            <geom size="0.003 0.002 0.003" type="box"/>
          </default>
          <default class="arm1_fingertip_pad_collision_3">
            <geom size="0.003 0.002 0.003" type="box"/>
          </default>
          <default class="arm1_fingertip_pad_collision_4">
            <geom size="0.003 0.002 0.0035" type="box"/>
          </default>
          <default class="arm1_fingertip_pad_collision_5">
            <geom size="0.003 0.002 0.0035" type="box"/>
          </default>
        </default>
      </default>
    </default>
  </default>

  <asset>
    <material name="arm0_white" class="arm0_panda"/>
    <material name="arm0_off_white" class="arm0_panda" rgba="0.901961 0.921569 0.929412 1"/>
    <material name="arm0_black" class="arm0_panda" rgba="0.25 0.25 0.25 1"/>
    <material name="arm0_green" class="arm0_panda" rgba="0 1 0 1"/>
    <material name="arm0_light_blue" class="arm0_panda" rgba="0.039216 0.541176 0.780392 1"/>
    <material name="arm1_white" class="arm1_panda"/>
    <material name="arm1_off_white" class="arm1_panda" rgba="0.901961 0.921569 0.929412 1"/>
    <material name="arm1_black" class="arm1_panda" rgba="0.25 0.25 0.25 1"/>
    <material name="arm1_green" class="arm1_panda" rgba="0 1 0 1"/>
    <material name="arm1_light_blue" class="arm1_panda" rgba="0.039216 0.541176 0.780392 1"/>
    <mesh name="arm0_link0_c" content_type="model/stl" file="link0.stl"/>
    <mesh name="arm0_link1_c" content_type="model/stl" file="link1.stl"/>
    <mesh name="arm0_link2_c" content_type="model/stl" file="link2.stl"/>
    <mesh name="arm0_link3_c" content_type="model/stl" file="link3.stl"/>
    <mesh name="arm0_link4_c" content_type="model/stl" file="link4.stl"/>
    <mesh name="arm0_link5_c0" content_type="model/obj" file="link5_collision_0.obj"/>
    <mesh name="arm0_link5_c1" content_type="model/obj" file="link5_collision_1.obj"/>
    <mesh name="arm0_link5_c2" content_type="model/obj" file="link5_collision_2.obj"/>
    <mesh name="arm0_link6_c" content_type="model/stl" file="link6.stl"/>
    <mesh name="arm0_link7_c" content_type="model/stl" file="link7.stl"/>
    <mesh name="arm0_hand_c" content_type="model/stl" file="hand.stl"/>
    <mesh name="arm0_link0_0" content_type="model/obj" file="link0_0.obj"/>
    <mesh name="arm0_link0_1" content_type="model/obj" file="link0_1.obj"/>
    <mesh name="arm0_link0_2" content_type="model/obj" file="link0_2.obj"/>
    <mesh name="arm0_link0_3" content_type="model/obj" file="link0_3.obj"/>
    <mesh name="arm0_link0_4" content_type="model/obj" file="link0_4.obj"/>
    <mesh name="arm0_link0_5" content_type="model/obj" file="link0_5.obj"/>
    <mesh name="arm0_link0_7" content_type="model/obj" file="link0_7.obj"/>
    <mesh name="arm0_link0_8" content_type="model/obj" file="link0_8.obj"/>
    <mesh name="arm0_link0_9" content_type="model/obj" file="link0_9.obj"/>
    <mesh name="arm0_link0_10" content_type="model/obj" file="link0_10.obj"/>
    <mesh name="arm0_link0_11" content_type="model/obj" file="link0_11.obj"/>
    <mesh name="arm0_link1" content_type="model/obj" file="link1.obj"/>
    <mesh name="arm0_link2" content_type="model/obj" file="link2.obj"/>
    <mesh name="arm0_link3_0" content_type="model/obj" file="link3_0.obj"/>
    <mesh name="arm0_link3_1" content_type="model/obj" file="link3_1.obj"/>
    <mesh name="arm0_link3_2" content_type="model/obj" file="link3_2.obj"/>
    <mesh name="arm0_link3_3" content_type="model/obj" file="link3_3.obj"/>
    <mesh name="arm0_link4_0" content_type="model/obj" file="link4_0.obj"/>
    <mesh name="arm0_link4_1" content_type="model/obj" file="link4_1.obj"/>
    <mesh name="arm0_link4_2" content_type="model/obj" file="link4_2.obj"/>
    <mesh name="arm0_link4_3" content_type="model/obj" file="link4_3.obj"/>
    <mesh name="arm0_link5_0" content_type="model/obj" file="link5_0.obj"/>
    <mesh name="arm0_link5_1" content_type="model/obj" file="link5_1.obj"/>
    <mesh name="arm0_link5_2" content_type="model/obj" file="link5_2.obj"/>
    <mesh name="arm0_link6_0" content_type="model/obj" file="link6_0.obj"/>
    <mesh name="arm0_link6_1" content_type="model/obj" file="link6_1.obj"/>
    <mesh name="arm0_link6_2" content_type="model/obj" file="link6_2.obj"/>
    <mesh name="arm0_link6_3" content_type="model/obj" file="link6_3.obj"/>
    <mesh name="arm0_link6_4" content_type="model/obj" file="link6_4.obj"/>
    <mesh name="arm0_link6_5" content_type="model/obj" file="link6_5.obj"/>
    <mesh name="arm0_link6_6" content_type="model/obj" file="link6_6.obj"/>
    <mesh name="arm0_link6_7" content_type="model/obj" file="link6_7.obj"/>
    <mesh name="arm0_link6_8" content_type="model/obj" file="link6_8.obj"/>
    <mesh name="arm0_link6_9" content_type="model/obj" file="link6_9.obj"/>
    <mesh name="arm0_link6_10" content_type="model/obj" file="link6_10.obj"/>
    <mesh name="arm0_link6_11" content_type="model/obj" file="link6_11.obj"/>
    <mesh name="arm0_link6_12" content_type="model/obj" file="link6_12.obj"/>
    <mesh name="arm0_link6_13" content_type="model/obj" file="link6_13.obj"/>
    <mesh name="arm0_link6_14" content_type="model/obj" file="link6_14.obj"/>
    <mesh name="arm0_link6_15" content_type="model/obj" file="link6_15.obj"/>
    <mesh name="arm0_link6_16" content_type="model/obj" file="link6_16.obj"/>
    <mesh name="arm0_link7_0" content_type="model/obj" file="link7_0.obj"/>
    <mesh name="arm0_link7_1" content_type="model/obj" file="link7_1.obj"/>
    <mesh name="arm0_link7_2" content_type="model/obj" file="link7_2.obj"/>
    <mesh name="arm0_link7_3" content_type="model/obj" file="link7_3.obj"/>
    <mesh name="arm0_link7_4" content_type="model/obj" file="link7_4.obj"/>
    <mesh name="arm0_link7_5" content_type="model/obj" file="link7_5.obj"/>
    <mesh name="arm0_link7_6" content_type="model/obj" file="link7_6.obj"/>
    <mesh name="arm0_link7_7" content_type="model/obj" file="link7_7.obj"/>
    <mesh name="arm0_hand_0" content_type="model/obj" file="hand_0.obj"/>
    <mesh name="arm0_hand_1" content_type="model/obj" file="hand_1.obj"/>
    <mesh name="arm0_hand_2" content_type="model/obj" file="hand_2.obj"/>
    <mesh name="arm0_hand_3" content_type="model/obj" file="hand_3.obj"/>
    <mesh name="arm0_hand_4" content_type="model/obj" file="hand_4.obj"/>
    <mesh name="arm0_finger_0" content_type="model/obj" file="finger_0.obj"/>
    <mesh name="arm0_finger_1" content_type="model/obj" file="finger_1.obj"/>
    <mesh name="arm1_link0_c" file="link0.stl"/>
    <mesh name="arm1_link1_c" file="link1.stl"/>
    <mesh name="arm1_link2_c" file="link2.stl"/>
    <mesh name="arm1_link3_c" file="link3.stl"/>
    <mesh name="arm1_link4_c" file="link4.stl"/>
    <mesh name="arm1_link5_c0" file="link5_collision_0.obj"/>
    <mesh name="arm1_link5_c1" file="link5_collision_1.obj"/>
    <mesh name="arm1_link5_c2" file="link5_collision_2.obj"/>
    <mesh name="arm1_link6_c" file="link6.stl"/>
    <mesh name="arm1_link7_c" file="link7.stl"/>
    <mesh name="arm1_hand_c" file="hand.stl"/>
    <mesh name="arm1_link0_0" file="link0_0.obj"/>
    <mesh name="arm1_link0_1" file="link0_1.obj"/>
    <mesh name="arm1_link0_2" file="link0_2.obj"/>
    <mesh name="arm1_link0_3" file="link0_3.obj"/>
    <mesh name="arm1_link0_4" file="link0_4.obj"/>
    <mesh name="arm1_link0_5" file="link0_5.obj"/>
    <mesh name="arm1_link0_7" file="link0_7.obj"/>
    <mesh name="arm1_link0_8" file="link0_8.obj"/>
    <mesh name="arm1_link0_9" file="link0_9.obj"/>
    <mesh name="arm1_link0_10" file="link0_10.obj"/>
    <mesh name="arm1_link0_11" file="link0_11.obj"/>
    <mesh name="arm1_link1" file="link1.obj"/>
    <mesh name="arm1_link2" file="link2.obj"/>
    <mesh name="arm1_link3_0" file="link3_0.obj"/>
    <mesh name="arm1_link3_1" file="link3_1.obj"/>
    <mesh name="arm1_link3_2" file="link3_2.obj"/>
    <mesh name="arm1_link3_3" file="link3_3.obj"/>
    <mesh name="arm1_link4_0" file="link4_0.obj"/>
    <mesh name="arm1_link4_1" file="link4_1.obj"/>
    <mesh name="arm1_link4_2" file="link4_2.obj"/>
    <mesh name="arm1_link4_3" file="link4_3.obj"/>
    <mesh name="arm1_link5_0" file="link5_0.obj"/>
    <mesh name="arm1_link5_1" file="link5_1.obj"/>
    <mesh name="arm1_link5_2" file="link5_2.obj"/>
    <mesh name="arm1_link6_0" file="link6_0.obj"/>
    <mesh name="arm1_link6_1" file="link6_1.obj"/>
    <mesh name="arm1_link6_2" file="link6_2.obj"/>
    <mesh name="arm1_link6_3" file="link6_3.obj"/>
    <mesh name="arm1_link6_4" file="link6_4.obj"/>
    <mesh name="arm1_link6_5" file="link6_5.obj"/>
    <mesh name="arm1_link6_6" file="link6_6.obj"/>
    <mesh name="arm1_link6_7" file="link6_7.obj"/>
    <mesh name="arm1_link6_8" file="link6_8.obj"/>
    <mesh name="arm1_link6_9" file="link6_9.obj"/>
    <mesh name="arm1_link6_10" file="link6_10.obj"/>
    <mesh name="arm1_link6_11" file="link6_11.obj"/>
    <mesh name="arm1_link6_12" file="link6_12.obj"/>
    <mesh name="arm1_link6_13" file="link6_13.obj"/>
    <mesh name="arm1_link6_14" file="link6_14.obj"/>
    <mesh name="arm1_link6_15" file="link6_15.obj"/>
    <mesh name="arm1_link6_16" file="link6_16.obj"/>
    <mesh name="arm1_link7_0" file="link7_0.obj"/>
    <mesh name="arm1_link7_1" file="link7_1.obj"/>
    <mesh name="arm1_link7_2" file="link7_2.obj"/>
    <mesh name="arm1_link7_3" file="link7_3.obj"/>
    <mesh name="arm1_link7_4" file="link7_4.obj"/>
    <mesh name="arm1_link7_5" file="link7_5.obj"/>
    <mesh name="arm1_link7_6" file="link7_6.obj"/>
    <mesh name="arm1_link7_7" file="link7_7.obj"/>
    <mesh name="arm1_hand_0" file="hand_0.obj"/>
    <mesh name="arm1_hand_1" file="hand_1.obj"/>
    <mesh name="arm1_hand_2" file="hand_2.obj"/>
    <mesh name="arm1_hand_3" file="hand_3.obj"/>
    <mesh name="arm1_hand_4" file="hand_4.obj"/>
    <mesh name="arm1_finger_0" file="finger_0.obj"/>
    <mesh name="arm1_finger_1" file="finger_1.obj"/>
  </asset>

  <worldbody>
    <geom name="floor" size="1.2 1.2 0.05" type="plane" rgba="0.32 0.33 0.36 1"/>
    <geom name="backdrop" size="0.02 0.82 0.38" pos="-0.08 0.1 0.58" type="box" contype="0" conaffinity="0" rgba="0.26 0.28 0.32 1"/>
    <geom name="bin_a_pad" size="0.085 0.085 0.006" pos="0.25 0.15 0.422" type="box" contype="0" conaffinity="0" rgba="0.18 0.42 0.72 0.95"/>
    <geom name="bin_a_rim_north" size="0.085 0.006 0.012" pos="0.25 0.235 0.434" type="box" contype="0" conaffinity="0" rgba="0.12 0.28 0.5 1"/>
    <geom name="bin_a_rim_south" size="0.085 0.006 0.012" pos="0.25 0.065 0.434" type="box" contype="0" conaffinity="0" rgba="0.12 0.28 0.5 1"/>
    <geom name="bin_a_rim_east" size="0.006 0.085 0.012" pos="0.335 0.15 0.434" type="box" contype="0" conaffinity="0" rgba="0.12 0.28 0.5 1"/>
    <geom name="bin_a_rim_west" size="0.006 0.085 0.012" pos="0.165 0.15 0.434" type="box" contype="0" conaffinity="0" rgba="0.12 0.28 0.5 1"/>
    <geom name="station_1_pad" size="0.085 0.085 0.006" pos="0.75 0.15 0.422" type="box" contype="0" conaffinity="0" rgba="0.82 0.55 0.18 0.95"/>
    <geom name="station_1_rim_north" size="0.085 0.006 0.012" pos="0.75 0.235 0.434" type="box" contype="0" conaffinity="0" rgba="0.58 0.38 0.1 1"/>
    <geom name="station_1_rim_south" size="0.085 0.006 0.012" pos="0.75 0.065 0.434" type="box" contype="0" conaffinity="0" rgba="0.58 0.38 0.1 1"/>
    <geom name="station_1_rim_east" size="0.006 0.085 0.012" pos="0.835 0.15 0.434" type="box" contype="0" conaffinity="0" rgba="0.58 0.38 0.1 1"/>
    <geom name="station_1_rim_west" size="0.006 0.085 0.012" pos="0.665 0.15 0.434" type="box" contype="0" conaffinity="0" rgba="0.58 0.38 0.1 1"/>
    <geom name="bin_b_pad" size="0.085 0.085 0.006" pos="0.25 -0.15 0.422" type="box" contype="0" conaffinity="0" rgba="0.18 0.42 0.72 0.95"/>
    <geom name="bin_b_rim_north" size="0.085 0.006 0.012" pos="0.25 -0.065 0.434" type="box" contype="0" conaffinity="0" rgba="0.12 0.28 0.5 1"/>
    <geom name="bin_b_rim_south" size="0.085 0.006 0.012" pos="0.25 -0.235 0.434" type="box" contype="0" conaffinity="0" rgba="0.12 0.28 0.5 1"/>
    <geom name="bin_b_rim_east" size="0.006 0.085 0.012" pos="0.335 -0.15 0.434" type="box" contype="0" conaffinity="0" rgba="0.12 0.28 0.5 1"/>
    <geom name="bin_b_rim_west" size="0.006 0.085 0.012" pos="0.165 -0.15 0.434" type="box" contype="0" conaffinity="0" rgba="0.12 0.28 0.5 1"/>
    <geom name="station_2_pad" size="0.085 0.085 0.006" pos="0.75 -0.15 0.422" type="box" contype="0" conaffinity="0" rgba="0.82 0.55 0.18 0.95"/>
    <geom name="station_2_rim_north" size="0.085 0.006 0.012" pos="0.75 -0.065 0.434" type="box" contype="0" conaffinity="0" rgba="0.58 0.38 0.1 1"/>
    <geom name="station_2_rim_south" size="0.085 0.006 0.012" pos="0.75 -0.235 0.434" type="box" contype="0" conaffinity="0" rgba="0.58 0.38 0.1 1"/>
    <geom name="station_2_rim_east" size="0.006 0.085 0.012" pos="0.835 -0.15 0.434" type="box" contype="0" conaffinity="0" rgba="0.58 0.38 0.1 1"/>
    <geom name="station_2_rim_west" size="0.006 0.085 0.012" pos="0.665 -0.15 0.434" type="box" contype="0" conaffinity="0" rgba="0.58 0.38 0.1 1"/>
    <site name="bin_a" pos="0.25 0.15 0.44" size="0.004" group="3" rgba="0 0 0 0"/>
    <site name="station_1" pos="0.75 0.15 0.44" size="0.004" group="3" rgba="0 0 0 0"/>
    <site name="bin_b" pos="0.25 -0.15 0.44" size="0.004" group="3" rgba="0 0 0 0"/>
    <site name="station_2" pos="0.75 -0.15 0.44" size="0.004" group="3" rgba="0 0 0 0"/>
    <site name="conveyor_infeed" pos="0.17 -0.3 0.455" size="0.004" group="3" rgba="0 0 0 0"/>
    <site name="conveyor_pick" pos="0.42 -0.3 0.455" size="0.004" group="3" rgba="0 0 0 0"/>
    <site name="conveyor_end" pos="0.83 -0.3 0.455" size="0.004" group="3" rgba="0 0 0 0"/>
    <camera name="dashboard" pos="0.55 0 1.05" quat="0.961394 0.275174 0 0" fovy="48"/>
    <light pos="0.9 0.35 1.6" dir="-0.477809 -0.130312 -0.868744" diffuse="0.85 0.82 0.78" specular="0.25 0.25 0.25"/>
    <light pos="-0.15 -0.55 1.3" dir="0.140181 0.327089 -0.934539" diffuse="0.35 0.38 0.45" specular="0.05 0.05 0.05"/>
    <body name="table" pos="0.5 0 0.4">
      <geom name="table_top" size="0.45 0.35 0.02" type="box" rgba="0.5 0.4 0.3 1"/>
      <geom name="table_skirt" size="0.44 0.34 0.05" pos="0 0 -0.055" type="box" contype="0" conaffinity="0" rgba="0.38 0.32 0.26 1"/>
    </body>
    <body name="part_1" pos="0.22 0.12 0.46">
      <joint name="part_1_free" type="free"/>
      <geom name="part_1_geom" size="0.022 0.022 0.018" type="box" mass="0.06" rgba="0.95 0.85 0.15 1"/>
      <site name="part_1_tip" pos="0 0 0" size="0.004" group="3" rgba="0 0 0 0"/>
    </body>
    <body name="part_2" pos="0.25 0.15 0.46">
      <joint name="part_2_free" type="free"/>
      <geom name="part_2_geom" size="0.022 0.022 0.018" type="box" mass="0.06" rgba="0.25 0.45 0.92 1"/>
      <site name="part_2_tip" pos="0 0 0" size="0.004" group="3" rgba="0 0 0 0"/>
    </body>
    <body name="part_3" pos="0.28 0.18 0.46">
      <joint name="part_3_free" type="free"/>
      <geom name="part_3_geom" size="0.022 0.022 0.018" type="box" mass="0.06" rgba="0.22 0.72 0.38 1"/>
      <site name="part_3_tip" pos="0 0 0" size="0.004" group="3" rgba="0 0 0 0"/>
    </body>
    <body name="conveyor_frame" pos="0.5 -0.3 0.42">
      <geom name="conveyor_belt_surface" size="0.38 0.06 0.008" pos="0 0 0.005" type="box" friction="1.2" rgba="0.12 0.12 0.14 1"/>
      <geom name="conveyor_rail_left" size="0.38 0.008 0.018" pos="0 0.072 0.02" type="box" contype="0" conaffinity="0" rgba="0.35 0.35 0.38 1"/>
      <geom name="conveyor_rail_right" size="0.38 0.008 0.018" pos="0 -0.072 0.02" type="box" contype="0" conaffinity="0" rgba="0.35 0.35 0.38 1"/>
      <geom name="conveyor_roller_in" size="0.025 0.006" pos="-0.36 0 0.012" type="cylinder" contype="0" conaffinity="0" rgba="0.5 0.5 0.55 1"/>
      <geom name="conveyor_roller_out" size="0.025 0.006" pos="0.36 0 0.012" type="cylinder" contype="0" conaffinity="0" rgba="0.5 0.5 0.55 1"/>
      <geom name="conveyor_pick_tape" size="0.05 0.045 0.001" pos="-0.08 0 0.014" type="box" contype="0" conaffinity="0" rgba="0.92 0.78 0.18 0.75"/>
    </body>
    <light name="arm0_top" pos="-0.22 0.35 2" dir="0 0 -1" mode="trackcom"/>
    <body name="arm0_link0" childclass="arm0_panda" pos="-0.22 0.35 0" quat="0.707107 0 0 0.707107">
      <inertial pos="-0.041018 -0.00014 0.049974" quat="0.00630474 0.751245 0.00741774 0.659952" mass="0.629769" diaginertia="0.00430465 0.00387984 0.00313051"/>
      <geom class="arm0_visual" material="arm0_off_white" mesh="arm0_link0_0"/>
      <geom class="arm0_visual" material="arm0_black" mesh="arm0_link0_1"/>
      <geom class="arm0_visual" material="arm0_off_white" mesh="arm0_link0_2"/>
      <geom class="arm0_visual" material="arm0_black" mesh="arm0_link0_3"/>
      <geom class="arm0_visual" material="arm0_off_white" mesh="arm0_link0_4"/>
      <geom class="arm0_visual" material="arm0_black" mesh="arm0_link0_5"/>
      <geom class="arm0_visual" material="arm0_white" mesh="arm0_link0_7"/>
      <geom class="arm0_visual" material="arm0_white" mesh="arm0_link0_8"/>
      <geom class="arm0_visual" material="arm0_black" mesh="arm0_link0_9"/>
      <geom class="arm0_visual" material="arm0_off_white" mesh="arm0_link0_10"/>
      <geom class="arm0_visual" material="arm0_white" mesh="arm0_link0_11"/>
      <geom class="arm0_collision" mesh="arm0_link0_c"/>
      <body name="arm0_link1" pos="0 0 0.333">
        <inertial pos="0.003875 0.002081 -0.04762" quat="0.711549 0.00634377 -0.0131124 0.702485" mass="4.97068" diaginertia="0.707137 0.703435 0.00852456"/>
        <joint name="arm0_joint1" pos="0 0 0" axis="0 0 1"/>
        <geom class="arm0_visual" material="arm0_white" mesh="arm0_link1"/>
        <geom class="arm0_collision" mesh="arm0_link1_c"/>
        <body name="arm0_link2" quat="0.707107 -0.707107 0 0">
          <inertial pos="-0.003141 -0.02872 0.003495" quat="-0.168175 0.828366 -0.122878 0.520027" mass="0.646926" diaginertia="0.0310326 0.0283001 0.00273425"/>
          <joint name="arm0_joint2" pos="0 0 0" axis="0 0 1" range="-1.7628 1.7628"/>
          <geom class="arm0_visual" material="arm0_white" mesh="arm0_link2"/>
          <geom class="arm0_collision" mesh="arm0_link2_c"/>
          <body name="arm0_link3" pos="0 -0.316 0" quat="0.707107 0.707107 0 0">
            <inertial pos="0.027518 0.039252 -0.066502" quat="0.662769 -0.00678331 0.252053 0.705096" mass="3.2286" diaginertia="0.0415014 0.0414793 0.00124635"/>
            <joint name="arm0_joint3" pos="0 0 0" axis="0 0 1"/>
            <geom class="arm0_visual" material="arm0_white" mesh="arm0_link3_0"/>
            <geom class="arm0_visual" material="arm0_white" mesh="arm0_link3_1"/>
            <geom class="arm0_visual" material="arm0_white" mesh="arm0_link3_2"/>
            <geom class="arm0_visual" material="arm0_black" mesh="arm0_link3_3"/>
            <geom class="arm0_collision" mesh="arm0_link3_c"/>
            <body name="arm0_link4" pos="0.0825 0 0" quat="0.707107 0.707107 0 0">
              <inertial pos="-0.05317 0.104419 0.027454" quat="0.65058 0.529822 -0.0962034 0.535518" mass="3.5879" diaginertia="0.0349596 0.0281483 0.0106201"/>
              <joint name="arm0_joint4" pos="0 0 0" axis="0 0 1" range="-3.0718 -0.0698"/>
              <geom class="arm0_visual" material="arm0_white" mesh="arm0_link4_0"/>
              <geom class="arm0_visual" material="arm0_white" mesh="arm0_link4_1"/>
              <geom class="arm0_visual" material="arm0_black" mesh="arm0_link4_2"/>
              <geom class="arm0_visual" material="arm0_white" mesh="arm0_link4_3"/>
              <geom class="arm0_collision" mesh="arm0_link4_c"/>
              <body name="arm0_link5" pos="-0.0825 0.384 0" quat="0.707107 -0.707107 0 0">
                <inertial pos="-0.011953 0.041065 -0.038437" quat="0.987313 -0.0121954 0.0719187 -0.141037" mass="1.22595" diaginertia="0.0367625 0.0288531 0.00803437"/>
                <joint name="arm0_joint5" pos="0 0 0" axis="0 0 1"/>
                <geom class="arm0_visual" material="arm0_black" mesh="arm0_link5_0"/>
                <geom class="arm0_visual" material="arm0_white" mesh="arm0_link5_1"/>
                <geom class="arm0_visual" material="arm0_white" mesh="arm0_link5_2"/>
                <geom class="arm0_collision" mesh="arm0_link5_c0"/>
                <geom class="arm0_collision" mesh="arm0_link5_c1"/>
                <geom class="arm0_collision" mesh="arm0_link5_c2"/>
                <body name="arm0_link6" quat="0.707107 0.707107 0 0">
                  <inertial pos="0.060149 -0.014117 -0.010517" quat="0.101075 0.59332 0.0287227 0.798079" mass="1.66656" diaginertia="0.00584276 0.00431037 0.00159787"/>
                  <joint name="arm0_joint6" pos="0 0 0" axis="0 0 1" range="-0.0175 3.7525"/>
                  <geom class="arm0_visual" material="arm0_off_white" mesh="arm0_link6_0"/>
                  <geom class="arm0_visual" material="arm0_white" mesh="arm0_link6_1"/>
                  <geom class="arm0_visual" material="arm0_black" mesh="arm0_link6_2"/>
                  <geom class="arm0_visual" material="arm0_white" mesh="arm0_link6_3"/>
                  <geom class="arm0_visual" material="arm0_white" mesh="arm0_link6_4"/>
                  <geom class="arm0_visual" material="arm0_white" mesh="arm0_link6_5"/>
                  <geom class="arm0_visual" material="arm0_white" mesh="arm0_link6_6"/>
                  <geom class="arm0_visual" material="arm0_light_blue" mesh="arm0_link6_7"/>
                  <geom class="arm0_visual" material="arm0_light_blue" mesh="arm0_link6_8"/>
                  <geom class="arm0_visual" material="arm0_black" mesh="arm0_link6_9"/>
                  <geom class="arm0_visual" material="arm0_black" mesh="arm0_link6_10"/>
                  <geom class="arm0_visual" material="arm0_white" mesh="arm0_link6_11"/>
                  <geom class="arm0_visual" material="arm0_green" mesh="arm0_link6_12"/>
                  <geom class="arm0_visual" material="arm0_white" mesh="arm0_link6_13"/>
                  <geom class="arm0_visual" material="arm0_black" mesh="arm0_link6_14"/>
                  <geom class="arm0_visual" material="arm0_black" mesh="arm0_link6_15"/>
                  <geom class="arm0_visual" material="arm0_white" mesh="arm0_link6_16"/>
                  <geom class="arm0_collision" mesh="arm0_link6_c"/>
                  <body name="arm0_link7" pos="0.088 0 0" quat="0.707107 0.707107 0 0">
                    <inertial pos="0.010517 -0.004252 0.061597" quat="0.992939 -0.0762041 0.0733595 -0.0537067" mass="0.735522" diaginertia="0.0127345 0.0101055 0.00451803"/>
                    <joint name="arm0_joint7" pos="0 0 0" axis="0 0 1"/>
                    <geom class="arm0_visual" material="arm0_white" mesh="arm0_link7_0"/>
                    <geom class="arm0_visual" material="arm0_black" mesh="arm0_link7_1"/>
                    <geom class="arm0_visual" material="arm0_black" mesh="arm0_link7_2"/>
                    <geom class="arm0_visual" material="arm0_black" mesh="arm0_link7_3"/>
                    <geom class="arm0_visual" material="arm0_black" mesh="arm0_link7_4"/>
                    <geom class="arm0_visual" material="arm0_black" mesh="arm0_link7_5"/>
                    <geom class="arm0_visual" material="arm0_black" mesh="arm0_link7_6"/>
                    <geom class="arm0_visual" material="arm0_white" mesh="arm0_link7_7"/>
                    <geom class="arm0_collision" mesh="arm0_link7_c"/>
                    <body name="arm0_hand" pos="0 0 0.107" quat="0.92388 0 0 -0.382683">
                      <inertial pos="-0.01 0 0.03" mass="0.73" diaginertia="0.001 0.0025 0.0017"/>
                      <geom class="arm0_visual" material="arm0_off_white" mesh="arm0_hand_0"/>
                      <geom class="arm0_visual" material="arm0_black" mesh="arm0_hand_1"/>
                      <geom class="arm0_visual" material="arm0_black" mesh="arm0_hand_2"/>
                      <geom class="arm0_visual" material="arm0_white" mesh="arm0_hand_3"/>
                      <geom class="arm0_visual" material="arm0_off_white" mesh="arm0_hand_4"/>
                      <geom class="arm0_collision" mesh="arm0_hand_c"/>
                      <site name="arm0_ee" pos="0 0 0.103" size="0.008"/>
                      <body name="arm0_left_finger" pos="0 0 0.0584">
                        <inertial pos="0 0 0" mass="0.015" diaginertia="2.375e-06 2.375e-06 7.5e-07"/>
                        <joint name="arm0_finger_joint1" class="arm0_finger" pos="0 0 0" axis="0 1 0"/>
                        <geom class="arm0_visual" material="arm0_off_white" mesh="arm0_finger_0"/>
                        <geom class="arm0_visual" material="arm0_black" mesh="arm0_finger_1"/>
                        <geom class="arm0_collision" mesh="arm0_finger_0"/>
                        <geom class="arm0_fingertip_pad_collision_1" pos="0 0.0055 0.0445"/>
                        <geom class="arm0_fingertip_pad_collision_2" pos="0.0055 0.002 0.05"/>
                        <geom class="arm0_fingertip_pad_collision_3" pos="-0.0055 0.002 0.05"/>
                        <geom class="arm0_fingertip_pad_collision_4" pos="0.0055 0.002 0.0395"/>
                        <geom class="arm0_fingertip_pad_collision_5" pos="-0.0055 0.002 0.0395"/>
                      </body>
                      <body name="arm0_right_finger" pos="0 0 0.0584" quat="0 0 0 1">
                        <inertial pos="0 0 0" mass="0.015" diaginertia="2.375e-06 2.375e-06 7.5e-07"/>
                        <joint name="arm0_finger_joint2" class="arm0_finger" pos="0 0 0" axis="0 1 0"/>
                        <geom class="arm0_visual" material="arm0_off_white" mesh="arm0_finger_0"/>
                        <geom class="arm0_visual" material="arm0_black" mesh="arm0_finger_1"/>
                        <geom class="arm0_collision" mesh="arm0_finger_0"/>
                        <geom class="arm0_fingertip_pad_collision_1" pos="0 0.0055 0.0445"/>
                        <geom class="arm0_fingertip_pad_collision_2" pos="0.0055 0.002 0.05"/>
                        <geom class="arm0_fingertip_pad_collision_3" pos="-0.0055 0.002 0.05"/>
                        <geom class="arm0_fingertip_pad_collision_4" pos="0.0055 0.002 0.0395"/>
                        <geom class="arm0_fingertip_pad_collision_5" pos="-0.0055 0.002 0.0395"/>
                      </body>
                    </body>
                  </body>
                </body>
              </body>
            </body>
          </body>
        </body>
      </body>
    </body>
    <light name="arm1_top" pos="-0.22 -0.15 2" dir="0 0 -1" mode="trackcom"/>
    <body name="arm1_link0" childclass="arm1_panda" pos="-0.22 -0.15 0" quat="0.707107 0 0 0.707107">
      <inertial pos="-0.041018 -0.00014 0.049974" quat="0.00630474 0.751245 0.00741774 0.659952" mass="0.629769" diaginertia="0.00430465 0.00387984 0.00313051"/>
      <geom class="arm1_visual" material="arm1_off_white" mesh="arm1_link0_0"/>
      <geom class="arm1_visual" material="arm1_black" mesh="arm1_link0_1"/>
      <geom class="arm1_visual" material="arm1_off_white" mesh="arm1_link0_2"/>
      <geom class="arm1_visual" material="arm1_black" mesh="arm1_link0_3"/>
      <geom class="arm1_visual" material="arm1_off_white" mesh="arm1_link0_4"/>
      <geom class="arm1_visual" material="arm1_black" mesh="arm1_link0_5"/>
      <geom class="arm1_visual" material="arm1_white" mesh="arm1_link0_7"/>
      <geom class="arm1_visual" material="arm1_white" mesh="arm1_link0_8"/>
      <geom class="arm1_visual" material="arm1_black" mesh="arm1_link0_9"/>
      <geom class="arm1_visual" material="arm1_off_white" mesh="arm1_link0_10"/>
      <geom class="arm1_visual" material="arm1_white" mesh="arm1_link0_11"/>
      <geom class="arm1_collision" mesh="arm1_link0_c"/>
      <body name="arm1_link1" pos="0 0 0.333">
        <inertial pos="0.003875 0.002081 -0.04762" quat="0.711549 0.00634377 -0.0131124 0.702485" mass="4.97068" diaginertia="0.707137 0.703435 0.00852456"/>
        <joint name="arm1_joint1" pos="0 0 0" axis="0 0 1"/>
        <geom class="arm1_visual" material="arm1_white" mesh="arm1_link1"/>
        <geom class="arm1_collision" mesh="arm1_link1_c"/>
        <body name="arm1_link2" quat="0.707107 -0.707107 0 0">
          <inertial pos="-0.003141 -0.02872 0.003495" quat="-0.168175 0.828366 -0.122878 0.520027" mass="0.646926" diaginertia="0.0310326 0.0283001 0.00273425"/>
          <joint name="arm1_joint2" pos="0 0 0" axis="0 0 1" range="-1.7628 1.7628"/>
          <geom class="arm1_visual" material="arm1_white" mesh="arm1_link2"/>
          <geom class="arm1_collision" mesh="arm1_link2_c"/>
          <body name="arm1_link3" pos="0 -0.316 0" quat="0.707107 0.707107 0 0">
            <inertial pos="0.027518 0.039252 -0.066502" quat="0.662769 -0.00678331 0.252053 0.705096" mass="3.2286" diaginertia="0.0415014 0.0414793 0.00124635"/>
            <joint name="arm1_joint3" pos="0 0 0" axis="0 0 1"/>
            <geom class="arm1_visual" material="arm1_white" mesh="arm1_link3_0"/>
            <geom class="arm1_visual" material="arm1_white" mesh="arm1_link3_1"/>
            <geom class="arm1_visual" material="arm1_white" mesh="arm1_link3_2"/>
            <geom class="arm1_visual" material="arm1_black" mesh="arm1_link3_3"/>
            <geom class="arm1_collision" mesh="arm1_link3_c"/>
            <body name="arm1_link4" pos="0.0825 0 0" quat="0.707107 0.707107 0 0">
              <inertial pos="-0.05317 0.104419 0.027454" quat="0.65058 0.529822 -0.0962034 0.535518" mass="3.5879" diaginertia="0.0349596 0.0281483 0.0106201"/>
              <joint name="arm1_joint4" pos="0 0 0" axis="0 0 1" range="-3.0718 -0.0698"/>
              <geom class="arm1_visual" material="arm1_white" mesh="arm1_link4_0"/>
              <geom class="arm1_visual" material="arm1_white" mesh="arm1_link4_1"/>
              <geom class="arm1_visual" material="arm1_black" mesh="arm1_link4_2"/>
              <geom class="arm1_visual" material="arm1_white" mesh="arm1_link4_3"/>
              <geom class="arm1_collision" mesh="arm1_link4_c"/>
              <body name="arm1_link5" pos="-0.0825 0.384 0" quat="0.707107 -0.707107 0 0">
                <inertial pos="-0.011953 0.041065 -0.038437" quat="0.987313 -0.0121954 0.0719187 -0.141037" mass="1.22595" diaginertia="0.0367625 0.0288531 0.00803437"/>
                <joint name="arm1_joint5" pos="0 0 0" axis="0 0 1"/>
                <geom class="arm1_visual" material="arm1_black" mesh="arm1_link5_0"/>
                <geom class="arm1_visual" material="arm1_white" mesh="arm1_link5_1"/>
                <geom class="arm1_visual" material="arm1_white" mesh="arm1_link5_2"/>
                <geom class="arm1_collision" mesh="arm1_link5_c0"/>
                <geom class="arm1_collision" mesh="arm1_link5_c1"/>
                <geom class="arm1_collision" mesh="arm1_link5_c2"/>
                <body name="arm1_link6" quat="0.707107 0.707107 0 0">
                  <inertial pos="0.060149 -0.014117 -0.010517" quat="0.101075 0.59332 0.0287227 0.798079" mass="1.66656" diaginertia="0.00584276 0.00431037 0.00159787"/>
                  <joint name="arm1_joint6" pos="0 0 0" axis="0 0 1" range="-0.0175 3.7525"/>
                  <geom class="arm1_visual" material="arm1_off_white" mesh="arm1_link6_0"/>
                  <geom class="arm1_visual" material="arm1_white" mesh="arm1_link6_1"/>
                  <geom class="arm1_visual" material="arm1_black" mesh="arm1_link6_2"/>
                  <geom class="arm1_visual" material="arm1_white" mesh="arm1_link6_3"/>
                  <geom class="arm1_visual" material="arm1_white" mesh="arm1_link6_4"/>
                  <geom class="arm1_visual" material="arm1_white" mesh="arm1_link6_5"/>
                  <geom class="arm1_visual" material="arm1_white" mesh="arm1_link6_6"/>
                  <geom class="arm1_visual" material="arm1_light_blue" mesh="arm1_link6_7"/>
                  <geom class="arm1_visual" material="arm1_light_blue" mesh="arm1_link6_8"/>
                  <geom class="arm1_visual" material="arm1_black" mesh="arm1_link6_9"/>
                  <geom class="arm1_visual" material="arm1_black" mesh="arm1_link6_10"/>
                  <geom class="arm1_visual" material="arm1_white" mesh="arm1_link6_11"/>
                  <geom class="arm1_visual" material="arm1_green" mesh="arm1_link6_12"/>
                  <geom class="arm1_visual" material="arm1_white" mesh="arm1_link6_13"/>
                  <geom class="arm1_visual" material="arm1_black" mesh="arm1_link6_14"/>
                  <geom class="arm1_visual" material="arm1_black" mesh="arm1_link6_15"/>
                  <geom class="arm1_visual" material="arm1_white" mesh="arm1_link6_16"/>
                  <geom class="arm1_collision" mesh="arm1_link6_c"/>
                  <body name="arm1_link7" pos="0.088 0 0" quat="0.707107 0.707107 0 0">
                    <inertial pos="0.010517 -0.004252 0.061597" quat="0.992939 -0.0762041 0.0733595 -0.0537067" mass="0.735522" diaginertia="0.0127345 0.0101055 0.00451803"/>
                    <joint name="arm1_joint7" pos="0 0 0" axis="0 0 1"/>
                    <geom class="arm1_visual" material="arm1_white" mesh="arm1_link7_0"/>
                    <geom class="arm1_visual" material="arm1_black" mesh="arm1_link7_1"/>
                    <geom class="arm1_visual" material="arm1_black" mesh="arm1_link7_2"/>
                    <geom class="arm1_visual" material="arm1_black" mesh="arm1_link7_3"/>
                    <geom class="arm1_visual" material="arm1_black" mesh="arm1_link7_4"/>
                    <geom class="arm1_visual" material="arm1_black" mesh="arm1_link7_5"/>
                    <geom class="arm1_visual" material="arm1_black" mesh="arm1_link7_6"/>
                    <geom class="arm1_visual" material="arm1_white" mesh="arm1_link7_7"/>
                    <geom class="arm1_collision" mesh="arm1_link7_c"/>
                    <body name="arm1_hand" pos="0 0 0.107" quat="0.92388 0 0 -0.382683">
                      <inertial pos="-0.01 0 0.03" mass="0.73" diaginertia="0.001 0.0025 0.0017"/>
                      <geom class="arm1_visual" material="arm1_off_white" mesh="arm1_hand_0"/>
                      <geom class="arm1_visual" material="arm1_black" mesh="arm1_hand_1"/>
                      <geom class="arm1_visual" material="arm1_black" mesh="arm1_hand_2"/>
                      <geom class="arm1_visual" material="arm1_white" mesh="arm1_hand_3"/>
                      <geom class="arm1_visual" material="arm1_off_white" mesh="arm1_hand_4"/>
                      <geom class="arm1_collision" mesh="arm1_hand_c"/>
                      <site name="arm1_ee" pos="0 0 0.103" size="0.008"/>
                      <body name="arm1_left_finger" pos="0 0 0.0584">
                        <inertial pos="0 0 0" mass="0.015" diaginertia="2.375e-06 2.375e-06 7.5e-07"/>
                        <joint name="arm1_finger_joint1" class="arm1_finger" pos="0 0 0" axis="0 1 0"/>
                        <geom class="arm1_visual" material="arm1_off_white" mesh="arm1_finger_0"/>
                        <geom class="arm1_visual" material="arm1_black" mesh="arm1_finger_1"/>
                        <geom class="arm1_collision" mesh="arm1_finger_0"/>
                        <geom class="arm1_fingertip_pad_collision_1" pos="0 0.0055 0.0445"/>
                        <geom class="arm1_fingertip_pad_collision_2" pos="0.0055 0.002 0.05"/>
                        <geom class="arm1_fingertip_pad_collision_3" pos="-0.0055 0.002 0.05"/>
                        <geom class="arm1_fingertip_pad_collision_4" pos="0.0055 0.002 0.0395"/>
                        <geom class="arm1_fingertip_pad_collision_5" pos="-0.0055 0.002 0.0395"/>
                      </body>
                      <body name="arm1_right_finger" pos="0 0 0.0584" quat="0 0 0 1">
                        <inertial pos="0 0 0" mass="0.015" diaginertia="2.375e-06 2.375e-06 7.5e-07"/>
                        <joint name="arm1_finger_joint2" class="arm1_finger" pos="0 0 0" axis="0 1 0"/>
                        <geom class="arm1_visual" material="arm1_off_white" mesh="arm1_finger_0"/>
                        <geom class="arm1_visual" material="arm1_black" mesh="arm1_finger_1"/>
                        <geom class="arm1_collision" mesh="arm1_finger_0"/>
                        <geom class="arm1_fingertip_pad_collision_1" pos="0 0.0055 0.0445"/>
                        <geom class="arm1_fingertip_pad_collision_2" pos="0.0055 0.002 0.05"/>
                        <geom class="arm1_fingertip_pad_collision_3" pos="-0.0055 0.002 0.05"/>
                        <geom class="arm1_fingertip_pad_collision_4" pos="0.0055 0.002 0.0395"/>
                        <geom class="arm1_fingertip_pad_collision_5" pos="-0.0055 0.002 0.0395"/>
                      </body>
                    </body>
                  </body>
                </body>
              </body>
            </body>
          </body>
        </body>
      </body>
    </body>
  </worldbody>

  <equality>
    <joint joint1="arm0_finger_joint1" joint2="arm0_finger_joint2" polycoef="0 1 0 0 0" solref="0.005" solimp="0.95 0.99"/>
    <joint joint1="arm1_finger_joint1" joint2="arm1_finger_joint2" polycoef="0 1 0 0 0" solref="0.005" solimp="0.95 0.99"/>
  </equality>

  <tendon>
    <fixed name="arm0_split">
      <joint joint="arm0_finger_joint1" coef="0.5"/>
      <joint joint="arm0_finger_joint2" coef="0.5"/>
    </fixed>
    <fixed name="arm1_split">
      <joint joint="arm1_finger_joint1" coef="0.5"/>
      <joint joint="arm1_finger_joint2" coef="0.5"/>
    </fixed>
  </tendon>

  <actuator>
    <general name="arm0_actuator1" class="arm0_panda" joint="arm0_joint1" gainprm="4500" biasprm="0 -4500 -450"/>
    <general name="arm0_actuator2" class="arm0_panda" joint="arm0_joint2" ctrlrange="-1.7628 1.7628" gainprm="4500" biasprm="0 -4500 -450"/>
    <general name="arm0_actuator3" class="arm0_panda" joint="arm0_joint3" gainprm="3500" biasprm="0 -3500 -350"/>
    <general name="arm0_actuator4" class="arm0_panda" joint="arm0_joint4" ctrlrange="-3.0718 -0.0698" gainprm="3500" biasprm="0 -3500 -350"/>
    <general name="arm0_actuator5" class="arm0_panda" joint="arm0_joint5" forcerange="-12 12" gainprm="2000" biasprm="0 -2000 -200"/>
    <general name="arm0_actuator6" class="arm0_panda" joint="arm0_joint6" ctrlrange="-0.0175 3.7525" forcerange="-12 12" gainprm="2000" biasprm="0 -2000 -200"/>
    <general name="arm0_actuator7" class="arm0_panda" joint="arm0_joint7" forcerange="-12 12" gainprm="2000" biasprm="0 -2000 -200"/>
    <general name="arm0_actuator8" class="arm0_panda" tendon="arm0_split" ctrlrange="0 255" forcerange="-100 100" gainprm="0.0156863" biasprm="0 -100 -10"/>
    <general name="arm1_actuator1" class="arm1_panda" joint="arm1_joint1" gainprm="4500" biasprm="0 -4500 -450"/>
    <general name="arm1_actuator2" class="arm1_panda" joint="arm1_joint2" ctrlrange="-1.7628 1.7628" gainprm="4500" biasprm="0 -4500 -450"/>
    <general name="arm1_actuator3" class="arm1_panda" joint="arm1_joint3" gainprm="3500" biasprm="0 -3500 -350"/>
    <general name="arm1_actuator4" class="arm1_panda" joint="arm1_joint4" ctrlrange="-3.0718 -0.0698" gainprm="3500" biasprm="0 -3500 -350"/>
    <general name="arm1_actuator5" class="arm1_panda" joint="arm1_joint5" forcerange="-12 12" gainprm="2000" biasprm="0 -2000 -200"/>
    <general name="arm1_actuator6" class="arm1_panda" joint="arm1_joint6" ctrlrange="-0.0175 3.7525" forcerange="-12 12" gainprm="2000" biasprm="0 -2000 -200"/>
    <general name="arm1_actuator7" class="arm1_panda" joint="arm1_joint7" forcerange="-12 12" gainprm="2000" biasprm="0 -2000 -200"/>
    <general name="arm1_actuator8" class="arm1_panda" tendon="arm1_split" ctrlrange="0 255" forcerange="-100 100" gainprm="0.0156863" biasprm="0 -100 -10"/>
  </actuator>

  <keyframe>
    <key name="arm0_home" qpos="0.22 0.12 0.46 1 0 0 0 0.25 0.15 0.46 1 0 0 0 0.28 0.18 0.46 1 0 0 0 0 0 0 -1.57079 0 1.57079 -0.7853 0.04 0.04 0 0 0 0 0 0 0 0 0" ctrl="0 0 0 -1.57079 0 1.57079 -0.7853 255 0 0 0 0 0 0 0 0"/>
    <key name="arm1_home" qpos="0.22 0.12 0.46 1 0 0 0 0.25 0.15 0.46 1 0 0 0 0.28 0.18 0.46 1 0 0 0 0 0 0 0 0 0 0 0 0 0 0 0 -1.57079 0 1.57079 -0.7853 0.04 0.04" ctrl="0 0 0 0 0 0 0 0 0 0 0 -1.57079 0 1.57079 -0.7853 255"/>
  </keyframe>
</mujoco>
